<?xml version="1.0" ?>
<!-- =================================================================================== -->
<!-- |    This document was autogenerated by xacro from xarco/qolo_with_rider.urdf.xarco | -->
<!-- |    EDITING THIS FILE BY HAND IS NOT RECOMMENDED                                 | -->
<!-- =================================================================================== -->
<robot name="qolo" xmlns:xacro="https://www.ros.org/wiki/xacro">
  <link name="qolo_main">
    <inertial>
      <origin rpy="0 0 0" xyz="-0.160 0 0.184"/>
      <mass value="50"/>
      <inertia ixx="22.23722770713" ixy="-0.04006835911" ixz="-0.02300035044" iyy="17.58011380849" iyz="-0.02387139307" izz="28.82981259528"/>
    </inertial>
    <visual>
      <geometry>
        <mesh filename="stl/qolo_main.stl" scale="1 1 1"/>
      </geometry>
      <origin rpy="0 0 0" xyz="0 0 0"/>
    </visual>
    <collision>
      <geometry>
        <mesh filename="stl/qolo_main.stl" scale="1 1 1"/>
      </geometry>
      <origin rpy="0 0 0" xyz="0 0 0"/>
    </collision>
  </link>
  <link name="wheel_right">
    <inertial>
      <origin rpy="0 0 0" xyz="0 0 0"/>
      <mass value="1.5"/>
      <inertia ixx="5.0001" ixy="0" ixz="0" iyy="1.0001" iyz="0" izz="5.0001"/>
    </inertial>
    <visual>
      <geometry>
        <mesh filename="stl/qolo_wheel.stl" scale="1 1 1"/>
      </geometry>
      <origin rpy="1.57079632679 0 0" xyz="0 0 0"/>
    </visual>
    <collision>
      <geometry>
        <mesh filename="stl/qolo_wheel.stl" scale="1 1 1"/>
      </geometry>
      <origin rpy="1.57079632679 0 0" xyz="0 0 0"/>
    </collision>
  </link>
  <joint name="qolo_main_to_wheel_right" type="continuous">
    <parent link="qolo_main"/>
    <child link="wheel_right"/>
    <origin xyz="0 0.2 0"/>
    <axis xyz="0 1 0"/>
  </joint>
  <link name="wheel_left">
    <inertial>
      <origin rpy="0 0 0" xyz="0 0 0"/>
      <mass value="1.5"/>
      <inertia ixx="5.0001" ixy="0" ixz="0" iyy="1.0001" iyz="0" izz="5.0001"/>
    </inertial>
    <visual>
      <geometry>
        <mesh filename="stl/qolo_wheel.stl" scale="1 1 1"/>
      </geometry>
      <origin rpy="-1.57079632679 0 0" xyz="0 0 0"/>
    </visual>
    <collision>
      <geometry>
        <mesh filename="stl/qolo_wheel.stl" scale="1 1 1"/>
      </geometry>
      <origin rpy="-1.57079632679 0 0" xyz="0 0 0"/>
    </collision>
  </link>
  <joint name="qolo_main_to_wheel_left" type="continuous">
    <parent link="qolo_main"/>
    <child link="wheel_left"/>
    <origin xyz="0 -0.2 0"/>
    <axis xyz="0 1 0"/>
  </joint>
  <link name="bumper">
    <inertial>
      <origin rpy="0 0 0" xyz="0 0 0"/>
      <mass value="1.5"/>
      <inertia ixx="0.02155077848" ixy="0.00000859993" ixz="0.00000332812" iyy="0.03332543416" iyz="0.00575422413" izz="0.04216038950"/>
    </inertial>
    <visual>
      <geometry>
        <mesh filename="stl/bumper.stl" scale="1 1 1"/>
      </geometry>
      <origin rpy="0 0 1.57079632679" xyz="0 0 0"/>
    </visual>
    <collision>
      <geometry>
        <mesh filename="stl/bumper.stl" scale="1 1 1"/>
      </geometry>
      <origin rpy="0 0 1.57079632679" xyz="0 0 0"/>
    </collision>
  </link>
  <joint name="qolo_main_to_bumper" type="fixed">
    <parent link="qolo_main"/>
    <child link="bumper"/>
    <origin xyz="0.035 0 0.015"/>
    <axis xyz="1 0 0"/>
  </joint>
  <link name="rider">
    <inertial>
      <origin rpy="0 0 0" xyz="0 0 0"/>
      <mass value="72"/>
      <inertia ixx="5.0001" ixy="0" ixz="0" iyy="1.0001" iyz="0" izz="5.0001"/>
    </inertial>
    <visual>
      <geometry>
        <mesh filename="stl/rider.stl" scale="1 1 1"/>
      </geometry>
      <origin rpy="0 0 0" xyz="0 0 0"/>
    </visual>
    <collision>
      <geometry>
        <mesh filename="stl/rider.stl" scale="1 1 1"/>
      </geometry>
      <origin rpy="0 0 0" xyz="0 0 0"/>
    </collision>
  </link>
  <joint name="qolo_main_to_rider" type="fixed">
    <parent link="qolo_main"/>
    <child link="rider"/>
    <origin xyz="0 0 0"/>
    <axis xyz="1 0 0"/>
  </joint>
</robot>
